Workbook

Sheet Engine Config Calc
A1: Engine Spec
A2: Blue items are drop-down selectors. Orange fields are inputs. Only type into the orange fields.
A3: Supports stock, CRP and WBI.
A4: Do not input propellants that have "IgnoreForIsp = True"
A5: Engine 1
A6: Inputs | B6: Isp (s) | C6: Thrust (kN)
A7: Stats (from cfg) | B7: 1019000 | C7: 350
A8: Outputs | B8: Ve (m/s) | C8: Flow (kg/s) | D8: Power (W) | E8: Esp (J/kg) | G8: Total flow (kg/s)
B9: =B7*9.80665 -> 9992976.3 | C9: =IFERROR(C7*1000/B9,0) -> 0.0350246 | D9: =C7*1000*B9 -> 3497541722500 | E9: =IFERROR(D9/C9,0) -> 9.9859576e+13 | G9: =SUM(B16:E16) -> 0.0350246 | H9: =IF($C$9>$G$9,"Input excesive",IF($C$9<$G$9,"Output excessive","Equal")) -> Equal
A12: Ratio (for cfg) | B12: 1 | C12: 1 | G12: Fraction | H12: ~ Re-input | I12: EC Target
A13: Name (dropdown) | B13: LqdHydrogen | C13: AntiHydrogen | E13: ElectricCharge | G13: =IFERROR(E15/I13,"-") -> 0 | H13: =IFERROR(E12/G13,"-") -> - | I13: 18.8
A14: Density (kg) | B14: =IFERROR(VLOOKUP(B13,Database!$A$2:$B$63,2,0),"-") -> 0.07085 | C14: =IFERROR(VLOOKUP(C13,Database!$A$2:$B$63,2,0),"-") -> 0.086 | D14: =IFERROR(VLOOKUP(D13,Database!$A$2:$B$63,2,0),"-") -> - | E14: 0
A15: Units/s (in-game) | B15: =IFERROR(C9*B12/SUM(B17:D17),"-") -> 0.22329997 | C15: =IFERROR(C9*C12/SUM(B17:D17),"-") -> 0.22329997 | D15: =IFERROR(C9*D12/SUM(B17:D17),"-") -> 0 | E15: =IFERROR(C9*E12/SUM(B17:D17),0) -> 0
A16: Mass flow (kg/s) | B16: =IFERROR($B$14*$B$15,"-") -> 0.015820803 | C16: =IFERROR(C14*C15,"-") -> 0.019203797 | D16: =IFERROR(D14*D15,"-") -> - | E16: =E14*E15 -> 0
A17: Ratio (U/s) | B17: =IFERROR(B12*B14,"-") -> 0.07085 | C17: =IFERROR(C12*C14,"-") -> 0.086 | D17: =IFERROR(D12*D14,"-") -> -
A20: Engine 2
A21: Inputs | B21: Isp (s) | C21: Thrust (kN)
A22: Stats (from cfg) | B22: 428 | C22: 1
A23: Outputs | B23: Ve (m/s) | C23: Flow (kg/s) | D23: Power (W) | E23: Esp (J/kg) | G23: Total flow (kg/s)
B24: =B22*9.80665 -> 4197.2462 | C24: =IFERROR(C22*1000/B24,0) -> 0.23825145 | D24: =C22*1000*B24 -> 4197246.2 | E24: =IFERROR(D24/C24,0) -> 17616876 | G24: =SUM(B31:E31) -> 0.23825145 | H24: =IF($C$9>$G$9,"Input excesive",IF($C$9<$G$9,"Output excessive","Equal")) -> Equal
A27: Ratio (for cfg) | B27: 1 | C27: 4 | E27: 5 | G27: Fraction | H27: ~ Re-input | I27: EC Target
A28: Name (dropdown) | B28: Oxium | C28: Propellium | E28: ElectricCharge | G28: =IFERROR(E30/I28,"-") -> 0.0088982935 | H28: =IFERROR(E27/G28,"-") -> 561.9055 | I28: 18.8
A29: Density (kg) | B29: =IFERROR(VLOOKUP(B28,Database!$A$2:$B$63,2,0),"-") -> 5.705 | C29: =IFERROR(VLOOKUP(C28,Database!$A$2:$B$63,2,0),"-") -> 0.354 | D29: =IFERROR(VLOOKUP(D28,Database!$A$2:$B$63,2,0),"-") -> - | E29: 0
A30: Units/s (in-game) | B30: =IFERROR(C24*B27/SUM(B32:D32),"-") -> 0.033457583 | C30: =IFERROR(C24*C27/SUM(B32:D32),"-") -> 0.13383033 | D30: =IFERROR(C24*D27/SUM(B32:D32),"-") -> 0 | E30: =IFERROR(C24*E27/SUM(B32:D32),0) -> 0.16728792
A31: Mass flow (kg/s) | B31: =IFERROR($B$29*$B$30,"-") -> 0.19087551 | C31: =IFERROR(C29*C30,"-") -> 0.047375938 | D31: =IFERROR(D29*D30,"-") -> - | E31: =E29*E30 -> 0
A32: Ratio (U/s) | B32: =IFERROR(B27*B29,"-") -> 5.705 | C32: =IFERROR(C27*C29,"-") -> 1.416 | D32: =IFERROR(D27*D29,"-") -> -

Sheet Database
A1: Name | B1: Density (kg) | G1: Name | H1: Chem Symbol | I1: Moles | J1: Molar mass
A2: LiquidFuel | B2: 5 | G2: Alumina | H2: Al2O3 | I2: 1 | J2: 101.96
A3: Oxidizer | B3: 5 | G3: Aluminium | H3: Al | I3: 1 | J3: 26.98
A4: Intake(Air/Atm) | B4: 5 | G4: Ammonia | H4: NH3 | I4: 1 | J4: 17.03
A5: MonoPropellant | B5: 4 | G5: ArgonGas | H5: Ar | I5: 1 | J5: 39.95
A6: Ore | B6: 10 | G6: Boron | H6: B | I6: 1 | J6: 39.95
A7: SolidFuel | B7: 7.5 | G7: Carbon | H7: C | I7: 1 | J7: 12.01
A8: XenonGas | B8: 0.1 | G8: CarbonDioxide | H8: CO2 | I8: 1 | J8: 44.01
G9: CarbonMonoxide | H9: CO | I9: 1 | J9: 28.01
A10: ____CRP____ | G10: Chlorine | H10: Cl2 | I10: 1 | J10: 35.45
A11: Antimatter | B11: =C11*1000 -> 1e-06 | C11: 1e-09 | G11: Depleted [Fuel/Uranium] | H11: U | I11: 1 | J11: 238.03
A12: Antimatter (FFT) | B12: =C12*1000 -> 0.01 | C12: 1e-05 | G12: Deuterium | H12: D / 2H | I12: 1 | J12: 2.014
A13: AntiHydrogen | B13: =C13*1000 -> 0.086 | C13: 8.6e-05 | G13: Dirt | H13: Sand (SiO2) | I13: 1 | J13: 60.08
A14: ArgonGas | B14: =C14*1000 -> 0.001784 | C14: 1.784e-06 | G14: EnrichedUranium | H14: U | I14: 1 | J14: 238.03
A15: AZ50 | B15: =C15*1000 -> 0.9 | C15: 0.0009 | G15: Ethanol | H15: C2H6O | I15: 1 | J15: 46.07
A16: Boron | B16: =C16*1000 -> 2.46 | C16: 0.00246 | G16: Ethanol75 | H16: C2H6O[3] + H2O[1] | I16: 1 | J16: 61.2068
A17: EnrichedUranium | B17: =C17*1000 -> 10.97 | C17: 0.01097 | G17: ExoticMinerals | H17: Xenotime (YPO4) | I17: 1 | J17: 183.88
A18: Ethanol | B18: =C18*1000 -> 0.789 | C18: 0.000789 | G18: Fluorine | H18: F2 | I18: 1 | J18: 19
A19: Ethanol75 | B19: =C19*1000 -> 0.84175 | C19: 0.00084175 | G19: FusionPellets | H19: D+He3 | I19: 1 | J19: =5.03 -> 5.03
A20: FissionPellets | B20: =C20*1000 -> 1 | C20: 0.001 | G20: Glykerol | H20: Glycerol (C3H8O3) | I20: 1 | J20: 92.09
A21: FusionPellets | B21: =C21*1000 -> 0.216 | C21: 0.000216 | G21: Gypsum | H21: Gypsum (CaSO4+2H2O) | I21: 1 | J21: 172.14
A22: Karbonite | B22: =C22*1000 -> 2.5 | C22: 0.0025 | G22: Helium-3 | H22: 3He | I22: 1 | J22: 3.016
A23: Karborundum | B23: =C23*1000 -> 5.8 | C23: 0.0058 | G23: Helium | H23: He / 4He | I23: 1 | J23: 4.002
A24: Kerosene | B24: =C24*1000 -> 0.82 | C24: 0.00082 | G24: HTP | H24: H2O2 | I24: 1 | J24: 34.01
A25: Lithium | B25: =C25*1000 -> 0.534 | C25: 0.000534 | G25: Hydrates | H25: Ferrihydrite (Fe2O3+0.5(H2O)) | I25: 1 | J25: 168.69
A26: LithiumSaltWater | B26: =C26*1000 -> 8.6964 | C26: 0.0086964 | G26: Hydrazine | H26: N2H4 | I26: 1 | J26: =(14.007*2)+(1.008*4) -> 32.046
A27: LqdAmmonia | B27: =C27*1000 -> 0.7021 | C27: 0.0007021 | G27: Hydrogen | H27: H2 | I27: 1 | J27: 2.02
A28: LqdCO | B28: =C28*1000 -> 0.79 | C28: 0.00079 | G28: Kerosene | H28: Dodecane (C12H26) | I28: 1 | J28: 170.34
A29: LqdCO2 | B29: =C29*1000 -> 1.17325 | C29: 0.00117325 | G29: Lithium | H29: Li | I29: 1 | J29: 6.94
A30: LqdDeuterium | B30: =C30*1000 -> 0.1624 | C30: 0.0001624 | G30: LqdAmmonia | H30: NH3 | I30: 1 | J30: 17.03
A31: LqdFluorine | B31: =C31*1000 -> 1.505 | C31: 0.001505 | G31: LqdCO | H31: CO | I31: 1 | J31: 28.01
A32: LqdHe3 | B32: =C32*1000 -> 0.059 | C32: 5.9e-05 | G32: LqdCO2 | H32: CO2 | I32: 1 | J32: 44.01
A33: LqdHydrogen | B33: =C33*1000 -> 0.07085 | C33: 7.085e-05 | G33: LqdDeuterium | H33: D / 2H | I33: 1 | J33: 2.014
A34: LqdMethane | B34: =C34*1000 -> 0.42561 | C34: 0.00042561 | G34: LqdHe3 | H34: 3He | I34: 1 | J34: 3.016
A35: LqdOxygen | B35: =C35*1000 -> 1.141 | C35: 0.001141 | G35: LqdHe | H35: He / 4He | I35: 1 | J35: 4.002
A36: LqdNitrogen | B36: =C36*1000 -> 0.824907 | C36: 0.000824907 | G36: LqdHydrogen | H36: H2 | I36: 1 | J36: 2.02
A37: Metal(s) | B37: =C37*1000 -> 7.8 | C37: 0.0078 | G37: LqdMethane | H37: CH4 | I37: 1 | J37: 16.05
A38: MetallicHydrogen | B38: =C38*1000 -> 7.085 | C38: 0.007085 | G38: LqdOxygen | H38: O2 | I38: 1 | J38: 32
A39: MMH | B39: =C39*1000 -> 0.88 | C39: 0.00088 | G39: LqdNitrogen | H39: N2 | I39: 1 | J39: 28.01
A40: NTO | B40: =C40*1000 -> 1.45 | C40: 0.00145 | G40: MetallicHydrogen | H40: H2 | I40: 1 | J40: =J36 -> 2.02
...

Sheet Samples
A1: Samples by @taniwha
A2: name | B2: Thrust(kN) | C2: Isp(s) | D2: Ve (m/s) | E2: flow(kg/s) | F2: power(W) | G2: J/kg
A3: 24-77 | B3: 16 | C3: 290 | D3: =C3*9.8066 -> 2843.914 | E3: =B3*1000/D3 -> 5.6260492 | F3: =B3*1000*D3/2 -> 22751312 | G3: =F3/E3 -> 4043923.4
A4: 48-7S | B4: 20 | C4: 320 | D4: =C4*9.8066 -> 3138.112 | E4: =B4*1000/D4 -> 6.3732588 | F4: =B4*1000*D4/2 -> 31381120 | G4: =F4/E4 -> 4923873.5
A5: aerospike | B5: 180 | C5: 340 | D5: =C5*9.8066 -> 3334.244 | E5: =B5*1000/D5 -> 53.985251 | F5: =B5*1000*D5/2 -> 300081960 | G5: =F5/E5 -> 5558591.5
A6: LV-1 | B6: 2 | C6: 315 | D6: =C6*9.8066 -> 3089.079 | E6: =B6*1000/D6 -> 0.64744217 | F6: =B6*1000*D6/2 -> 3089079 | G6: =F6/E6 -> 4771204.5
A7: LV-1R | B7: 2 | C7: 290 | D7: =C7*9.8066 -> 2843.914 | E7: =B7*1000/D7 -> 0.70325615 | F7: =B7*1000*D7/2 -> 2843914 | G7: =F7/E7 -> 4043923.4
A8: LV-909 | B8: 60 | C8: 345 | D8: =C8*9.8066 -> 3383.277 | E8: =B8*1000/D8 -> 17.734285 | F8: =B8*1000*D8/2 -> 101498310 | G8: =F8/E8 -> 5723281.6
A9: LV-N | B9: 60 | C9: 800 | D9: =C9*9.8066 -> 7845.28 | E9: =B9*1000/D9 -> 7.6479106 | F9: =B9*1000*D9/2 -> 235358400 | G9: =F9/E9 -> 30774209 | H9: LF only
A10: LV-T30 | B10: 240 | C10: 310 | D10: =C10*9.8066 -> 3040.046 | E10: =B10*1000/D10 -> 78.946174 | F10: =B10*1000*D10/2 -> 364805520 | G10: =F10/E10 -> 4620939.8
A11: LV-T45 | B11: 215 | C11: 320 | D11: =C11*9.8066 -> 3138.112 | E11: =B11*1000/D11 -> 68.512532 | F11: =B11*1000*D11/2 -> 337347040 | G11: =F11/E11 -> 4923873.5
A12: mainsail | B12: 1500 | C12: 310 | D12: =C12*9.8066 -> 3040.046 | E12: =B12*1000/D12 -> 493.41359 | F12: =B12*1000*D12/2 -> 2280034500 | G12: =F12/E12 -> 4620939.8
A13: Mk55 | B13: 120 | C13: 305 | D13: =C13*9.8066 -> 2991.013 | E13: =B13*1000/D13 -> 40.120187 | F13: =B13*1000*D13/2 -> 179460780 | G13: =F13/E13 -> 4473079.4
A14: poodle | B14: 250 | C14: 350 | D14: =C14*9.8066 -> 3432.31 | E14: =B14*1000/D14 -> 72.837244 | F14: =B14*1000*D14/2 -> 429038750 | G14: =F14/E14 -> 5890376
A15: SSME | B15: 1000 | C15: 315 | D15: =C15*9.8066 -> 3089.079 | E15: =B15*1000/D15 -> 323.72108 | F15: =B15*1000*D15/2 -> 1.5445395e+09 | G15: =F15/E15 -> 4771204.5
A16: skipper | B16: 650 | C16: 320 | D16: =C16*9.8066 -> 3138.112 | E16: =B16*1000/D16 -> 207.13091 | F16: =B16*1000*D16/2 -> 1019886400 | G16: =F16/E16 -> 4923873.5

Sheet Energy calcs
A1: Energy Calculators
A2: Basic
B3: Isp (s) | C3: Thrust (Vac, kN) | G3: c
B4: 203946 | C4: 2300 | G4: 299792458
B5: Ve (m/s) | C5: Flow (kg/s) | D5: Power (W) | E5: Power (J/kg)
B6: =B4*G7 -> 2000027 | C6: =IFERROR(C4*1000/B6,0) -> 1.1499845 | D6: =C4*1000*B6 -> 4600062194070 | E6: =IFERROR(D6/C6,0) -> 4.0001082e+12 | G6: ɡ0
B7: Ve (%c) | G7: 9.80665
B8: =B6/G4 -> 0.0066713721
A10: Advanced
B11: Isp (s) | C11: Thrust (Vac, kN)
B12: 960 | C12: =(C14*B14)/1000 -> 0.29543542
B13: Ve (m/s) | C13: Flow (kg/s) | D13: Power (W) | E13: Esp (J/kg)
B14: =B12*G7 -> 9414.384 | C14: =E14/D14 -> 0.03138128 | D14: 2824315200 | E14: =IFERROR((B14^2),0) -> 88630626
B16: Weight (t)
B17: Engine count | C17: Extra | D17: TWR per engine
B18: 1 | C18: 0 | D18: =C12/(B18*G7) -> 0.030126029
A21: Lightcraft
B22: Power (W) | C22: Thrust (kN) | D22: ElectricCharge (kW or kWh)
B23: 1000000000 | C23: =(B23/G4/1000) -> 0.003335641 | D23: =B23/1000 -> 1000000
A26: Reactor to engine
B27: Isp (s) | C27: Thrust (Vac, kN)
B28: =B30/G7 -> 749335.32 | C28: 3800
B29: Ve (m/s) | C29: Flow (kg/s) | D29: Power (W) | E29: Esp (J/kg)
B30: =(2*E30)^0.5 -> 7348469.2 | C30: =IFERROR(C28*1000/B30,0) -> 0.5171145 | D30: =C28*1000*B30 -> 2.7924183e+13 | E30: 27000000000000
B31: Ve (%c)
B32: =B30/G4 -> 0.024511855
A35: Exhaust gas velocity
B37: T | C37: 2130
B38: R | C38: 8.3144621
B39: M | C39: LqdHydrogen | D39: =IFERROR(VLOOKUP(C39,Database!$G$2:$J$59,4,FALSE),"-") -> 2.02 | E39: =D39/1000 -> 0.00202
C40: Water (CRP) | D40: =IFERROR(VLOOKUP(C40,Database!$G$2:$J$59,4,FALSE),"-") -> 18.02 | E40: =D40/1000 -> 0.01802
B41: γ | C41: 1.398
B42: Pe | C42: 0 | D42: =IFERROR(C42*101320,101.32) -> 0
B43: P | C43: 500 | D43: =C43*101320 -> 50660000
B45: (T*R)/M | C45: =(C37*C38)/E39 -> 8767229.8 | E45: =(C37*C38)/E40 -> 982786.03
B46: (2γ/γ-1) | C46: =(2*C41)/(C41-1) -> 7.0251256
B47: γ-1/γ | C47: =(C41-1)/C41 -> 0.28469242
B48: (1-(Pe^Z)/P) | C48: =1-((D42/D43)^C47) -> 1
C50: =C39 -> LqdHydrogen | E50: =C40 -> Water (CRP)
B51: Ve (m/s) | C51: =(C45*C46*C48)^0.5 -> 7847.9864 | E51: =(E45*C46*C48)^0.5 -> 2627.5836
...
