Workbook

Sheet Calc (Kg)
A1: Convert-O-Tron (Kilograms)
A2: Blue items are drop-down selectors. Orange fields are inputs. Only type into the orange fields.
A3: Supports stock, CRP (greater fractions of NFT, USI, RealFuels) and WBI.
A4: Does not support most of CRP (KSPI-E)
A5: Inputs
A6: Ratio (for cfg) | B6: 0 | C6: 0 | D6: 0 | E6: 0 | F6: 0 | G6: 0 | I6: Rate | J6: 1 | K6: u/sec | L6: =J7/J6 -> 1
A7: Name (dropdown) | I7: Total | J7: 1 | K7: units | L7: =IF(J8>0,L6-(J8*3600),0) -> 0
A8: Density (kg) | B8: =IFERROR(VLOOKUP(B7,Database!$A$3:$E$152,5,FALSE),"-") -> - | C8: =IFERROR(VLOOKUP(C7,Database!$A$3:$E$152,5,FALSE),"-") -> - | D8: =IFERROR(VLOOKUP(D7,Database!$A$3:$E$152,5,FALSE),"-") -> - | E8: =IFERROR(VLOOKUP(E7,Database!$A$3:$E$152,5,FALSE),"-") -> - | F8: =IFERROR(VLOOKUP(F7,Database!$A$3:$E$152,5,FALSE),"-") -> - | G8: =IFERROR(VLOOKUP(G7,Database!$A$3:$E$152,5,FALSE),"-") -> - | I8: Cycle | J8: =ROUNDDOWN(IF(L6>3600,L6/3600,0),0) -> 0 | K8: hr | L8: =ROUNDDOWN(IF(L7>0,L7/60,L6/60),0) -> 0
A9: Mass (mol) | B9: =IFERROR(VLOOKUP(B7,Database!$A$3:$E$152,4,FALSE),"-") -> - | C9: =IFERROR(VLOOKUP(C7,Database!$A$3:$E$152,4,FALSE),"-") -> - | D9: =IFERROR(VLOOKUP(D7,Database!$A$3:$E$152,4,FALSE),"-") -> - | E9: =IFERROR(VLOOKUP(E7,Database!$A$3:$E$152,4,FALSE),"-") -> - | F9: =IFERROR(VLOOKUP(F7,Database!$A$3:$E$152,4,FALSE),"-") -> - | G9: =IFERROR(VLOOKUP(G7,Database!$A$3:$E$152,4,FALSE),"-") -> - | J9: =IF(L8<60,L8,0) -> 0 | K9: min | L9: =IF(L6>0,L6-((J8*3600)+(L8*60)),0) -> 1
A10: Gross kg/s | B10: =IFERROR(B6*B8,"-") -> - | C10: =IFERROR(C6*C8,"-") -> - | D10: =IFERROR(D6*D8,"-") -> - | E10: =IFERROR(E6*E8,"-") -> - | F10: =IFERROR(F6*F8,"-") -> - | G10: =IFERROR(G6*G8,"-") -> - | J10: =IF(L9>0,L9,0) -> 1 | K10: sec
A11: Gross moles | B11: =IFERROR((B6*(B8*1000))/B9,"-") -> - | C11: =IFERROR((C6*(C8*1000))/C9,"-") -> - | D11: =IFERROR((D6*(D8*1000))/D9,"-") -> - | E11: =IFERROR((E6*(E8*1000))/E9,"-") -> - | F11: =IFERROR((F6*(F8*1000))/F9,"-") -> - | G11: =IFERROR((G6*(G8*1000))/G9,"-") -> -
A12: Net kg/s | B12: =SUM(B10:G10) -> 0
A15: Outputs
A16: Ratio (for cfg) | B16: 0 | C16: 0 | D16: 0 | E16: 0 | F16: 0 | G16: 0 | I16: Rate | J16: 1 | K16: u/sec | L16: =J17/J16 -> 1
A17: Name (dropdown) | I17: Total | J17: 1 | K17: units | L17: =IF(J18>0,L16-(J18*3600),0) -> 0
A18: Density (kg) | B18: =IFERROR(VLOOKUP(B17,Database!$A$3:$E$152,5,FALSE),"-") -> - | C18: =IFERROR(VLOOKUP(C17,Database!$A$3:$E$152,5,FALSE),"-") -> - | D18: =IFERROR(VLOOKUP(D17,Database!$A$3:$E$152,5,FALSE),"-") -> - | E18: =IFERROR(VLOOKUP(E17,Database!$A$3:$E$152,5,FALSE),"-") -> - | F18: =IFERROR(VLOOKUP(F17,Database!$A$3:$E$152,5,FALSE),"-") -> - | G18: =IFERROR(VLOOKUP(G17,Database!$A$3:$E$152,5,FALSE),"-") -> - | I18: Cycle | J18: =ROUNDDOWN(IF(L16>3600,L16/3600,0),0) -> 0 | K18: hr | L18: =ROUNDDOWN(IF(L17>0,L17/60,L16/60),0) -> 0
A19: Mass (mol) | B19: =IFERROR(VLOOKUP(B17,Database!$A$3:$E$152,4,FALSE),"-") -> - | C19: =IFERROR(VLOOKUP(C17,Database!$A$3:$E$152,4,FALSE),"-") -> - | D19: =IFERROR(VLOOKUP(D17,Database!$A$3:$E$152,4,FALSE),"-") -> - | E19: =IFERROR(VLOOKUP(E17,Database!$A$3:$E$152,4,FALSE),"-") -> - | F19: =IFERROR(VLOOKUP(F17,Database!$A$3:$E$152,4,FALSE),"-") -> - | G19: =IFERROR(VLOOKUP(G17,Database!$A$3:$E$152,4,FALSE),"-") -> - | J19: =IF(L18<60,L18,0) -> 0 | K19: min | L19: =IF(L16>0,L16-((J18*3600)+(L18*60)),0) -> 1
A20: Gross kg/s | B20: =IFERROR(B16*B18,"-") -> - | C20: =IFERROR(C16*C18,"-") -> - | D20: =IFERROR(D16*D18,"-") -> - | E20: =IFERROR(E16*E18,"-") -> - | F20: =IFERROR(F16*F18,"-") -> - | G20: =IFERROR(G16*G18,"-") -> - | J20: =IF(L19>0,L19,0) -> 1 | K20: sec
A21: Gross moles | B21: =IFERROR((B16*(B18*1000))/B19,"-") -> - | C21: =IFERROR((C16*(C18*1000))/C19,"-") -> - | D21: =IFERROR((D16*(D18*1000))/D19,"-") -> - | E21: =IFERROR((E16*(E18*1000))/E19,"-") -> - | F21: =IFERROR((F16*(F18*1000))/F19,"-") -> - | G21: =IFERROR((G16*(G18*1000))/G19,"-") -> -
A22: Net kg/s | B22: =SUM(B20:G20) -> 0
A25: I/O Ratio
A26: Bias | B26: =IF($B$12>$B$22,"Input excesive",IF($B$12<$B$22,"Output excessive","Equal")) -> Equal | C26: =IF($B$12>$B$22,B12/B22,IF($B$12<$B$22,B22/B12,1)) -> 1

Sheet Calc (Moles)
A1: Convert-O-Tron (Moles)
A2: Blue items are drop-down selectors. Orange fields are inputs. Only type into the orange fields.
A3: Supports stock and CRP (only popular resources where correlated IRL resources can be found).
A4: Does not support most of CRP (KSPI-E) or any of WBI.
A5: Inputs
A6: Moles | B6: 0 | C6: 0 | D6: 0 | E6: 0 | F6: 0 | G6: 0 | H6: 0 | I6: 0
A7: Name (dropdown)
A8: Mass (g/mol) | B8: =IFERROR(VLOOKUP(B7,Database!$A$3:$E$113,4,FALSE),"-") -> - | C8: =IFERROR(VLOOKUP(C7,Database!$A$3:$E$113,4,FALSE),"-") -> - | D8: =IFERROR(VLOOKUP(D7,Database!$A$3:$E$113,4,FALSE),"-") -> - | E8: =IFERROR(VLOOKUP(E7,Database!$A$3:$E$113,4,FALSE),"-") -> - | F8: =IFERROR(VLOOKUP(F7,Database!$A$3:$E$113,4,FALSE),"-") -> - | G8: =IFERROR(VLOOKUP(G7,Database!$A$3:$E$113,4,FALSE),"-") -> - | H8: =IFERROR(VLOOKUP(H7,Database!$A$3:$E$113,4,FALSE),"-") -> - | I8: =IFERROR(VLOOKUP(I7,Database!$A$3:$E$113,4,FALSE),"-") -> -
A9: Density (kg) | B9: =IFERROR(VLOOKUP(B7,Database!$A$3:$E$113,5,FALSE),"-") -> - | C9: =IFERROR(VLOOKUP(C7,Database!$A$3:$E$113,5,FALSE),"-") -> - | D9: =IFERROR(VLOOKUP(D7,Database!$A$3:$E$113,5,FALSE),"-") -> - | E9: =IFERROR(VLOOKUP(E7,Database!$A$3:$E$113,5,FALSE),"-") -> - | F9: =IFERROR(VLOOKUP(F7,Database!$A$3:$E$113,5,FALSE),"-") -> - | G9: =IFERROR(VLOOKUP(G7,Database!$A$3:$E$113,5,FALSE),"-") -> - | H9: =IFERROR(VLOOKUP(H7,Database!$A$3:$E$113,5,FALSE),"-") -> - | I9: =IFERROR(VLOOKUP(I7,Database!$A$3:$E$113,5,FALSE),"-") -> -
A10: Gross (g/mol) | B10: =IFERROR(B6*B8,0) -> 0 | C10: =IFERROR(C6*C8,"-") -> - | D10: =IFERROR(D6*D8,"-") -> - | E10: =IFERROR(E6*E8,"-") -> - | F10: =IFERROR(F6*F8,"-") -> - | G10: =IFERROR(G6*G8,"-") -> - | H10: =IFERROR(H6*H8,"-") -> - | I10: =IFERROR(I6*I8,"-") -> -
A11: Ratio (for cfg) | B11: =IFERROR(B10/(B9*1000),"-") -> - | C11: =IFERROR(C10/(C9*1000),"-") -> - | D11: =IFERROR(D10/(D9*1000),"-") -> - | E11: =IFERROR(E10/(E9*1000),"-") -> - | F11: =IFERROR(F10/(F9*1000),"-") -> - | G11: =IFERROR(G10/(G9*1000),"-") -> - | H11: =IFERROR(H10/(H9*1000),"-") -> - | I11: =IFERROR(I10/(I9*1000),"-") -> -
A12: Net (g/mol) | B12: =SUM(B10:I10) -> 0
A14: Ionization energy | B14: =IFERROR(VLOOKUP(B7,Database!$A$3:$G$113,7,FALSE),"-") -> - | C14: =IFERROR(VLOOKUP(C7,Database!$A$3:$G$113,7,FALSE),"-") -> - | D14: =IFERROR(VLOOKUP(D7,Database!$A$3:$G$113,7,FALSE),"-") -> - | E14: =IFERROR(VLOOKUP(E7,Database!$A$3:$G$113,7,FALSE),"-") -> - | F14: =IFERROR(VLOOKUP(F7,Database!$A$3:$G$113,7,FALSE),"-") -> - | G14: =IFERROR(VLOOKUP(G7,Database!$A$3:$G$113,7,FALSE),"-") -> - | H14: =IFERROR(VLOOKUP(H7,Database!$A$3:$G$113,7,FALSE),"-") -> - | I14: =IFERROR(VLOOKUP(I7,Database!$A$3:$G$113,7,FALSE),"-") -> -
B15: =IFERROR(B6*B14,0) -> 0 | C15: =IFERROR(C6*C14,0) -> 0 | D15: =IFERROR(D6*D14,0) -> 0 | E15: =IFERROR(E6*E14,0) -> 0 | F15: =IFERROR(F6*F14,0) -> 0 | G15: =IFERROR(G6*G14,0) -> 0 | H15: =IFERROR(H6*H14,0) -> 0 | I15: =IFERROR(I6*I14,0) -> 0
A16: Net (kW) | B16: =SUM(B15:I15)/20 -> 0
A19: Outputs
A20: Moles | B20: =B6*2 -> 0 | C20: 0 | D20: =B6*2 -> 0 | E20: =B6*10 -> 0 | F20: 0 | G20: 0 | H20: 0 | I20: 0
A21: Name (dropdown)
A22: Mass (g/mol) | B22: =IFERROR(VLOOKUP(B21,Database!$A$3:$G$113,4,FALSE),"-") -> - | C22: =IFERROR(VLOOKUP(C21,Database!$A$3:$G$113,4,FALSE),"-") -> - | D22: =IFERROR(VLOOKUP(D21,Database!$A$3:$G$113,4,FALSE),"-") -> - | E22: =IFERROR(VLOOKUP(E21,Database!$A$3:$G$113,4,FALSE),"-") -> - | F22: =IFERROR(VLOOKUP(F21,Database!$A$3:$G$113,4,FALSE),"-") -> - | G22: =IFERROR(VLOOKUP(G21,Database!$A$3:$G$113,4,FALSE),"-") -> - | H22: =IFERROR(VLOOKUP(H21,Database!$A$3:$G$113,4,FALSE),"-") -> - | I22: =IFERROR(VLOOKUP(I21,Database!$A$3:$G$113,4,FALSE),"-") -> -
A23: Density (kg) | B23: =IFERROR(VLOOKUP(B21,Database!$A$3:$G$113,5,FALSE),"-") -> - | C23: =IFERROR(VLOOKUP(C21,Database!$A$3:$G$113,5,FALSE),"-") -> - | D23: =IFERROR(VLOOKUP(D21,Database!$A$3:$G$113,5,FALSE),"-") -> - | E23: =IFERROR(VLOOKUP(E21,Database!$A$3:$G$113,5,FALSE),"-") -> - | F23: =IFERROR(VLOOKUP(F21,Database!$A$3:$G$113,5,FALSE),"-") -> - | G23: =IFERROR(VLOOKUP(G21,Database!$A$3:$G$113,5,FALSE),"-") -> - | H23: =IFERROR(VLOOKUP(H21,Database!$A$3:$G$113,5,FALSE),"-") -> - | I23: =IFERROR(VLOOKUP(I21,Database!$A$3:$G$113,5,FALSE),"-") -> -
A24: Gross (g/mol) | B24: =IFERROR(B20*B22,0) -> 0 | C24: =IFERROR(C20*C22,"-") -> - | D24: =IFERROR(D20*D22,"-") -> - | E24: =IFERROR(E20*E22,"-") -> - | F24: =IFERROR(F20*F22,"-") -> - | G24: =IFERROR(G20*G22,"-") -> - | H24: =IFERROR(H20*H22,"-") -> - | I24: =IFERROR(I20*I22,"-") -> -
A25: Ratio (for cfg) | B25: =IFERROR(B24/(B23*1000),"-") -> - | C25: =IFERROR(C24/(C23*1000),"-") -> - | D25: =IFERROR(D24/(D23*1000),"-") -> - | E25: =IFERROR(E24/(E23*1000),"-") -> - | F25: =IFERROR(F24/(F23*1000),"-") -> - | G25: =IFERROR(G24/(G23*1000),"-") -> - | H25: =IFERROR(H24/(H23*1000),"-") -> - | I25: =IFERROR(I24/(I23*1000),"-") -> -
A26: Net (g/mol) | B26: =SUM(B24:I24) -> 0
A28: Ionization energy | B28: =IFERROR(VLOOKUP(B21,Database!$A$3:$G$113,7,FALSE),"-") -> - | C28: =IFERROR(VLOOKUP(C21,Database!$A$3:$G$113,7,FALSE),"-") -> - | D28: =IFERROR(VLOOKUP(D21,Database!$A$3:$G$113,7,FALSE),"-") -> - | E28: =IFERROR(VLOOKUP(E21,Database!$A$3:$G$113,7,FALSE),"-") -> - | F28: =IFERROR(VLOOKUP(F21,Database!$A$3:$G$113,7,FALSE),"-") -> - | G28: =IFERROR(VLOOKUP(G21,Database!$A$3:$G$113,7,FALSE),"-") -> -
B29: =IFERROR(B20*B28,0) -> 0 | C29: =IFERROR(C20*C28,0) -> 0 | D29: =IFERROR(D20*D28,0) -> 0 | E29: =IFERROR(E20*E28,0) -> 0 | F29: =IFERROR(F20*F28,0) -> 0 | G29: =IFERROR(G20*G28,0) -> 0 | H29: =IFERROR(H20*H28,0) -> 0 | I29: =IFERROR(I20*I28,0) -> 0
A30: Net (kW) | B30: =SUM(B29:I29)/20 -> 0
A33: I/O Ratio
A34: Bias | B34: =IF($B$12>$B$26,"Input excesive",IF($B$12<$B$26,"Output excessive","Equal")) -> Equal | C34: =IF($B$12>$B$26,B12/B26,IF($B$12<$B$26,B26/B12,1)) -> 1
D36: =1/C34 -> 1

Sheet Database
A1: Resource | B1: Real world chemical | C1: unit cost | D1: molar mass (g/mol) | E1: density (kg/L) | F1: mole/gram scalar | G1: Ionization energy (J)
A3: Ore | B3: Biotite (Fe3+AlSi3O10+F2) + Calcite (CaCO3) | C3: 0.02 | D3: 576.85 | E3: =0.01*1000 -> 10 | F3: =D3/(E3 * 1000) -> 0.057685 | G3: 283.27
A4: LiquidFuel | B4: Dodecane (C12H26) | C4: 0.8 | D4: 170.34 | E4: =0.005*1000 -> 5 | F4: =D4/(E4 * 1000) -> 0.034068 | G4: 488.46 | J4: APCP | K4: Resource | L4: Notation | M4: mass (g/mol) | N4: %
A5: Oxidizer | B5: H2O2 | C5: 0.18 | D5: =54.4 -> 54.4 | E5: =0.005*1000 -> 5 | F5: =D5/(E5 * 1000) -> 0.01088 | G5: 54.4 | J5: Oxidizer | K5: Amonium Perchlorate | L5: NH4ClO4 | M5: 117.49 | N5: 0.7 | O5: 99 | P5: =M5*O5 -> 11631.51 | Q5: =P5/$P$8 -> 0.70146498
A6: MonoPropellant | B6: Hydrazine (N2H4) | C6: 1.2 | D6: =(14.007*2)+(1.008*4) -> 32.046 | E6: =0.004*1000 -> 4 | F6: =D6/(E6 * 1000) -> 0.0080115 | G6: 83.42 | J6: Fuel | K6: Aluminum | L6: Al | M6: 26.98 | N6: 0.15 | O6: 92 | P6: =M6*O6 -> 2482.16 | Q6: =P6/$P$8 -> 0.14969237
A7: XenonGas | B7: Xe | C7: 4 | D7: =131.29 -> 131.29 | E7: =0.0001*1000 -> 0.1 | F7: =D7/(E7 * 1000) -> 1.3129 | G7: 12.12 | J7: Binder | K7: HTPB | L7: (OH)2.(C4H6)45 | M7: 2468.07 | N7: 0.15 | O7: 1 | P7: =M7*O7 -> 2468.07 | Q7: =P7/$P$8 -> 0.14884264
A8: SolidFuel | B8: Ammonium Perchlorate[99] + Aluminium[92] + HTPB[1] | C8: 0.6 | D8: 1658.174 | E8: =0.0075*1000 -> 7.5 | F8: =D8/(E8 * 1000) -> 0.22108987 | P8: =SUM(P5:P7) -> 16581.74
A10: Aerozine50 | B10: Hydrazine + UDMH (50:50) | C10: 1.35 | D10: =SUM(($D$51*0.5)+($D$109*0.5)) -> 46.073 | E10: =0.0009*1000 -> 0.9 | F10: =D10/(E10 * 1000) -> 0.051192222 | G10: =(G51/2)+(G109/2) -> 1623.855
A11: Alumina | B11: Al2O3 | C11: 0.5 | D11: 101.96 | E11: =0.00398*1000 -> 3.98 | F11: =D11/(E11 * 1000) -> 0.02561809 | G11: 52.79
A12: Aluminium | B12: Al | C12: 1.5 | D12: 26.98 | E12: =0.00277*1000 -> 2.77 | F12: =D12/(E12 * 1000) -> 0.0097400722 | G12: 5.98
A13: Ammonia | B13: NH3 | C13: 0.00015 | D13: 17.03 | E13: =0.000000769*1000 -> 0.000769 | F13: =D13/(E13 * 1000) -> 22.145644 | G13: 55.3
A14: ArgonGas | B14: Ar | C14: 0.0105 | D14: 39.95 | E14: =0.000001784*1000 -> 0.001784 | F14: =D14/(E14 * 1000) -> 22.393498 | G14: 15.75
A15: Aniline | B15: C6H5+NH2 | C15: 0.5213333 | D15: 93.13 | E15: =0.00102*1000 -> 1.02 | F15: =D15/(E15 * 1000) -> 0.091303922 | G15: 177.22
A16: Beryllium | B16: Be | C16: 1.4 | D16: 9.01 | E16: =0.00185*1000 -> 1.85 | F16: =D16/(E16 * 1000) -> 0.0048702703 | G16: 9.32
A17: Beryl Oxide | B17: Be2O3 | C17: 0.8 | D17: 66.02 | E17: =0.00244518*1000 -> 2.44518 | F17: =D17/(E17 * 1000) -> 0.027000057 | G17: 59.47
A18: Buckminsterfullerene | B18: C60 | D18: 720.6 | E18: =0.126*1000 -> 126 | F18: =D18/(E18 * 1000) -> 0.0057190476 | G18: 675.6
A19: Boron | B19: B | C19: 0.851 | D19: 10.81 | E19: =0.00246*1000 -> 2.46 | F19: =D19/(E19 * 1000) -> 0.0043943089 | G19: 8.29
A20: Caesium | B20: Cs | C20: 77 | D20: 132.91 | E20: =0.00193*1000 -> 1.93 | F20: =D20/(E20 * 1000) -> 0.068865285 | G20: 3.89
A21: Calcium | B21: Ca | C21: 0.00015 | D21: 40.08 | E21: =0.00155*1000 -> 1.55 | F21: =D21/(E21 * 1000) -> 0.025858065 | G21: 6.11
A22: Carbon | B22: C | C22: 0 | D22: 12.01 | E22: =0.0021*1000 -> 2.1 | F22: =D22/(E22 * 1000) -> 0.0057190476 | G22: 11.26
A23: CarbonDioxide | B23: CO2 | C23: 2.8637e-06 | D23: 44.01 | E23: =0.000001951*1000 -> 0.001951 | F23: =D23/(E23 * 1000) -> 22.557663 | G23: 38.48
A24: CarbonMonoxide | B24: CO | C24: 3.32e-06 | D24: 28.01 | E24: =0.00000125*1000 -> 0.00125 | F24: =D24/(E24 * 1000) -> 22.408 | G24: 24.87
A25: Chemicals | B25: Minerals + Gypsum + Nitrogen | C25: 16 | D25: 558.47 | E25: =0.0025*1000 -> 2.5 | F25: =D25/(E25 * 1000) -> 0.223388 | G25: 373.39
A26: Chlorine | B26: Cl | C26: 0.00015 | D26: 35.45 | E26: =0.0032*1000 -> 3.2 | F26: =D26/(E26 * 1000) -> 0.011078125 | G26: 12.96
A27: Colony Supplies | C27: 15 | E27: =0.001556*1000 -> 1.556
A28: Depleted [Fuel/Uranium] | B28: U | C28: 0 | D28: 238.03 | E28: =0.01097*1000 -> 10.97 | F28: =D28/(E28 * 1000) -> 0.021698268 | G28: 6.19
A29: Deuterium | B29: D / 2H | C29: 0.00028 | D29: 2.014 | E29: =0.00000018*1000 -> 0.00018 | F29: =D29/(E29 * 1000) -> 11.188889 | G29: 13.59
A30: Diborane | B30: B2H6 | C30: 4.21 | D30: 27.67 | E30: =0.000421*1000 -> 0.421 | F30: =D30/(E30 * 1000) -> 0.065724466 | G30: 98.12
A31: Dirt | B31: Sand (SiO2) | C31: 0.3 | D31: 60.08 | E31: =0.0016*1000 -> 1.6 | F31: =D31/(E31 * 1000) -> 0.03755 | G31: 35.37
A32: EnrichedUranium | B32: U | C32: 865 | D32: 238.03 | E32: =0.01097*1000 -> 10.97 | F32: =D32/(E32 * 1000) -> 0.021698268 | G32: 6.19
A33: Ethanol | B33: C2H6O | C33: 0.12624 | D33: 46.07 | E33: =0.000789*1000 -> 0.789 | F33: =D33/(E33 * 1000) -> 0.058390368 | G33: 117.67
A34: Ethanol75 | B34: C2H6O[3] + H2O[1] | C34: 0.12624 | D34: 61.2068 | E34: =0.00084175*1000 -> 0.84175 | F34: =D34/(E34 * 1000) -> 0.072713751 | G34: 393.8
A35: ExoticMinerals | B35: Pezzottaite (Cs(Be2Li)Al2Si6O18) + Loparite custom (RNbO3) | C35: 160 | D35: 953.5281 | E35: =0.0025*1000 -> 2.5 | F35: =D35/(E35 * 1000) -> 0.38141124 | G35: 386.86
A36: Fertilizer | B36: N-P-K concentrate (N22.P2O5.(K2O)3) | C36: 2 | D36: 852.6832 | E36: =0.001*1000 -> 1 | F36: =D36/(E36 * 1000) -> 0.8526832 | G36: 475.54
A37: FissileFuel | B37: UF4 + 2LiF + BeF2 | C37: 920 | D37: 412.91 | E37: =0.001556*1000 -> 1.556 | F37: =D37/(E37 * 1000) -> 0.26536632
A38: FissilePebbles | B38: U + SiC | C38: 1150 | D38: 278.13 | E38: =0.00321*1000 -> 3.21 | F38: =D38/(E38 * 1000) -> 0.08664486
A39: FissionPellets | C39: 12 | E39: =0.001*1000 -> 1
A40: FissionPulses | B40: (Fe + Be2O3)2.5 + (U)1.1 | C40: 175 | D40: 741.308 | E40: =0.05*1000 -> 50 | F40: =D40/(E40 * 1000) -> 0.01482616
A41: Fluorine | B41: F | C41: 0.010176 | D41: 19 | E41: =0.000001696*1000 -> 0.001696 | F41: =D41/(E41 * 1000) -> 11.20283 | G41: 17.42
A42: Food (TAC) | B42: Fatty acid complex (C5O2H11) | C42: 0.2388747 | D42: 103.14 | E42: =0.00028102905982906*1000 -> 0.28102906 | F42: =D42/(E42 * 1000) -> 0.36700831 | G42: 233.01
...

Sheet Ionization energy
A1: Composition
A2: Element | D2: Qty | F2: Energy | G2: Mass | J2: Energy | K2: Mass | L2: Diatomic
A3: Symbol | B3: Name | C3: Diatomic | F3: J | G3: g/mol
A4: Yb | B4: =IFERROR(VLOOKUP(A4,$A$25:$D$139,2,FALSE),"-") -> Ytterbium | C4: =IF(L4="Y","Yes","-") -> - | D4: 1 | E4: =D4*$D$18 -> 1 | F4: =IFERROR(E4*J4,0) -> 6.25 | G4: =IFERROR(E4*K4,0) -> 173.05 | J4: =IFERROR(VLOOKUP(A4,$A$25:$D$139,3,FALSE),"-") -> 6.25 | K4: =IFERROR(VLOOKUP(A4,$A$25:$D$139,4,FALSE),"-") -> 173.05 | L4: =IFERROR(VLOOKUP(A4,$A$25:$E$124,5,FALSE),"-") -> 0
A5: Si | B5: =IFERROR(VLOOKUP(A5,$A$25:$D$139,2,FALSE),"-") -> Silicon | C5: =IF(L5="Y","Yes","-") -> - | D5: 11 | E5: =D5*$D$18 -> 11 | F5: =IFERROR(E5*J5,0) -> 89.65 | G5: =IFERROR(E5*K5,0) -> 308.935 | J5: =IFERROR(VLOOKUP(A5,$A$25:$D$139,3,FALSE),"-") -> 8.15 | K5: =IFERROR(VLOOKUP(A5,$A$25:$D$139,4,FALSE),"-") -> 28.085 | L5: =IFERROR(VLOOKUP(A5,$A$25:$E$124,5,FALSE),"-") -> 0
A6: c | B6: =IFERROR(VLOOKUP(A6,$A$25:$D$139,2,FALSE),"-") -> Carbon | C6: =IF(L6="Y","Yes","-") -> - | E6: =D6*$D$18 -> 0 | F6: =IFERROR(E6*J6,0) -> 0 | G6: =IFERROR(E6*K6,0) -> 0 | J6: =IFERROR(VLOOKUP(A6,$A$25:$D$139,3,FALSE),"-") -> 11.26 | K6: =IFERROR(VLOOKUP(A6,$A$25:$D$139,4,FALSE),"-") -> 12.011 | L6: =IFERROR(VLOOKUP(A6,$A$25:$E$124,5,FALSE),"-") -> 0
B7: =IFERROR(VLOOKUP(A7,$A$25:$D$139,2,FALSE),"-") -> - | C7: =IF(L7="Y","Yes","-") -> - | E7: =D7*$D$18 -> 0 | F7: =IFERROR(E7*J7,0) -> 0 | G7: =IFERROR(E7*K7,0) -> 0 | J7: =IFERROR(VLOOKUP(A7,$A$25:$D$139,3,FALSE),"-") -> - | K7: =IFERROR(VLOOKUP(A7,$A$25:$D$139,4,FALSE),"-") -> - | L7: =IFERROR(VLOOKUP(A7,$A$25:$E$124,5,FALSE),"-") -> -
B8: =IFERROR(VLOOKUP(A8,$A$25:$D$139,2,FALSE),"-") -> - | C8: =IF(L8="Y","Yes","-") -> - | E8: =D8*$D$18 -> 0 | F8: =IFERROR(E8*J8,0) -> 0 | G8: =IFERROR(E8*K8,0) -> 0 | J8: =IFERROR(VLOOKUP(A8,$A$25:$D$139,3,FALSE),"-") -> - | K8: =IFERROR(VLOOKUP(A8,$A$25:$D$139,4,FALSE),"-") -> - | L8: =IFERROR(VLOOKUP(A8,$A$25:$E$124,5,FALSE),"-") -> -
B9: =IFERROR(VLOOKUP(A9,$A$25:$D$139,2,FALSE),"-") -> - | C9: =IF(L9="Y","Yes","-") -> - | E9: =D9*$D$18 -> 0 | F9: =IFERROR(E9*J9,0) -> 0 | G9: =IFERROR(E9*K9,0) -> 0 | J9: =IFERROR(VLOOKUP(A9,$A$25:$D$139,3,FALSE),"-") -> - | K9: =IFERROR(VLOOKUP(A9,$A$25:$D$139,4,FALSE),"-") -> - | L9: =IFERROR(VLOOKUP(A9,$A$25:$E$124,5,FALSE),"-") -> -
B10: =IFERROR(VLOOKUP(A10,$A$25:$D$139,2,FALSE),"-") -> - | C10: =IF(L10="Y","Yes","-") -> - | E10: =D10*$D$18 -> 0 | F10: =IFERROR(E10*J10,0) -> 0 | G10: =IFERROR(E10*K10,0) -> 0 | J10: =IFERROR(VLOOKUP(A10,$A$25:$D$139,3,FALSE),"-") -> - | K10: =IFERROR(VLOOKUP(A10,$A$25:$D$139,4,FALSE),"-") -> - | L10: =IFERROR(VLOOKUP(A10,$A$25:$E$124,5,FALSE),"-") -> -
B11: =IFERROR(VLOOKUP(A11,$A$25:$D$139,2,FALSE),"-") -> - | C11: =IF(L11="Y","Yes","-") -> - | E11: =D11*$D$18 -> 0 | F11: =IFERROR(E11*J11,0) -> 0 | G11: =IFERROR(E11*K11,0) -> 0 | J11: =IFERROR(VLOOKUP(A11,$A$25:$D$139,3,FALSE),"-") -> - | K11: =IFERROR(VLOOKUP(A11,$A$25:$D$139,4,FALSE),"-") -> - | L11: =IFERROR(VLOOKUP(A11,$A$25:$E$124,5,FALSE),"-") -> -
B12: =IFERROR(VLOOKUP(A12,$A$25:$D$139,2,FALSE),"-") -> - | C12: =IF(L12="Y","Yes","-") -> - | E12: =D12*$D$18 -> 0 | F12: =IFERROR(E12*J12,0) -> 0 | G12: =IFERROR(E12*K12,0) -> 0 | J12: =IFERROR(VLOOKUP(A12,$A$25:$D$139,3,FALSE),"-") -> - | K12: =IFERROR(VLOOKUP(A12,$A$25:$D$139,4,FALSE),"-") -> - | L12: =IFERROR(VLOOKUP(A12,$A$25:$E$124,5,FALSE),"-") -> -
B13: =IFERROR(VLOOKUP(A13,$A$25:$D$139,2,FALSE),"-") -> - | C13: =IF(L13="Y","Yes","-") -> - | E13: =D13*$D$18 -> 0 | F13: =IFERROR(E13*J13,0) -> 0 | G13: =IFERROR(E13*K13,0) -> 0 | J13: =IFERROR(VLOOKUP(A13,$A$25:$D$139,3,FALSE),"-") -> - | K13: =IFERROR(VLOOKUP(A13,$A$25:$D$139,4,FALSE),"-") -> - | L13: =IFERROR(VLOOKUP(A13,$A$25:$E$124,5,FALSE),"-") -> -
B14: =IFERROR(VLOOKUP(A14,$A$25:$D$139,2,FALSE),"-") -> - | C14: =IF(L14="Y","Yes","-") -> - | E14: =D14*$D$18 -> 0 | F14: =IFERROR(E14*J14,0) -> 0 | G14: =IFERROR(E14*K14,0) -> 0 | J14: =IFERROR(VLOOKUP(A14,$A$25:$D$139,3,FALSE),"-") -> - | K14: =IFERROR(VLOOKUP(A14,$A$25:$D$139,4,FALSE),"-") -> - | L14: =IFERROR(VLOOKUP(A14,$A$25:$E$124,5,FALSE),"-") -> -
B15: =IFERROR(VLOOKUP(A15,$A$25:$D$139,2,FALSE),"-") -> - | C15: =IF(L15="Y","Yes","-") -> - | E15: =D15*$D$18 -> 0 | F15: =IFERROR(E15*J15,0) -> 0 | G15: =IFERROR(E15*K15,0) -> 0 | J15: =IFERROR(VLOOKUP(A15,$A$25:$D$139,3,FALSE),"-") -> - | K15: =IFERROR(VLOOKUP(A15,$A$25:$D$139,4,FALSE),"-") -> - | L15: =IFERROR(VLOOKUP(A15,$A$25:$E$124,5,FALSE),"-") -> -
D17: Pre-mult | F17: kW
D18: 1 | F18: =SUM(F4:F15) -> 95.9 | G18: =SUM(G4:G15) -> 481.985
F19: =F18/20 -> 4.795
A22: Resource DB
C23: Energy | D23: Weight | E23: Diatomic
C24: 1st | D24: g/mol
A25: H | B25: Hydrogen | C25: 13.59 | D25: 1.008 | E25: Y
A26: He | B26: Helium | C26: 24.58 | D26: 4.0026
A27: Li | B27: Lithium | C27: 5.39 | D27: 7
A28: Be | B28: Beryllium | C28: 9.32 | D28: 9.0121
A29: B | B29: Boron | C29: 8.29 | D29: 10.81
A30: C | B30: Carbon | C30: 11.26 | D30: 12.011
A31: N | B31: Nitrogen | C31: 14.53 | D31: 14.007 | E31: Y
A32: O | B32: Oxygen | C32: 13.61 | D32: 15.999 | E32: Y
A33: F | B33: Fluorine | C33: 17.42 | D33: 18.998 | E33: Y
A34: Ne | B34: Neon | C34: 21.56 | D34: 20.18
A35: Na | B35: Sodium | C35: 5.13 | D35: 22.9897
A36: Mg | B36: Magnesium | C36: 7.64 | D36: 24.305
A37: Al | B37: Aluminium | C37: 5.98 | D37: 26.9815
A38: Si | B38: Silicon | C38: 8.15 | D38: 28.085
A39: P | B39: Phosphorus | C39: 10.48 | D39: 90.9737
A40: S | B40: Sulfur | C40: 10.36 | D40: 32.07
A41: Cl | B41: Chlorine | C41: 12.96 | D41: 18.9984 | E41: Y
A42: Ar | B42: Argon | C42: 15.75 | D42: 39.9
A43: K | B43: Potassium | C43: 4.34 | D43: 39.0983
...
